<?xml version="1.0" encoding="utf-8"?>
<!-- This URDF was automatically created by SolidWorks to URDF Exporter! Originally created by Stephen Brawner (brawner@gmail.com) 
     Commit Version: 1.6.0-4-g7f85cfe  Build Version: 1.6.7995.38578
     For more information, please see http://wiki.ros.org/sw_urdf_exporter -->
<robot
  name="hanyang_gripper_isaac_description">
  <link
    name="eef">
      <visual>
        <origin xyz="0 0 0" rpy="0 0 0"/>
        <geometry>
          <box size="0.015 0.015 0.015"/>
        </geometry>
        <material name="eef">
          <color rgba="1 0 1 0.1"/>
        </material>
      </visual>
  </link>
  <link
    name="finger_1_1_link">
    <inertial>
      <origin
        xyz="0.00349284549789534 -0.050025048950824 -0.0210812927299723"
        rpy="0 0 0" />
      <mass
        value="0.154570337903723" />
      <inertia
        ixx="3.89039858559283E-05"
        ixy="2.89920889852035E-06"
        ixz="1.14231873725166E-06"
        iyy="4.83952164769888E-05"
        iyz="-7.44428141881446E-07"
        izz="4.54599283772954E-05" />
    </inertial>
    <visual>
      <origin
        xyz="0 0 0"
        rpy="0 0 0" />
      <geometry>
        <mesh
          filename="package://hanyang_gripper_isaac_description/meshes/finger_1_1_link.STL" />
      </geometry>
      <material
        name="">
        <color
          rgba="0.792156862745098 0.819607843137255 0.933333333333333 1" />
      </material>
    </visual>
    <collision>
      <origin
        xyz="0 0 0"
        rpy="0 0 0" />
      <geometry>
        <mesh
          filename="package://hanyang_gripper_isaac_description/meshes/finger_1_1_link.STL" />
      </geometry>
    </collision>
  </link>
  <joint
    name="finger_1_1_joint"
    type="prismatic">
    <origin
      xyz="0.062623 0.041584 0.22997"
      rpy="1.5708 0 1.0472" />
    <parent
      link="eef" />
    <child
      link="finger_1_1_link" />
    <axis
      xyz="1 0 0" />
    <dynamics damping="10.0"/>
    <limit
      lower="0"
      upper="0.129"
      effort="20"
      velocity="10" />
  </joint>
  <link
    name="finger_1_2_link">
    <inertial>
      <origin
        xyz="-0.010542450944798 0.00172194122196023 -0.0278026060177003"
        rpy="0 0 0" />
      <mass
        value="0.02455101194144" />
      <inertia
        ixx="2.82122578994014E-06"
        ixy="-4.48263705420781E-09"
        ixz="1.31635862466435E-06"
        iyy="5.58049262105453E-06"
        iyz="2.68007985844004E-08"
        izz="5.0262302090158E-06" />
    </inertial>
    <visual>
      <origin
        xyz="0 0 0"
        rpy="0 0 0" />
      <geometry>
        <mesh
          filename="package://hanyang_gripper_isaac_description/meshes/finger_1_2_link.STL" />
      </geometry>
      <material
        name="">
        <color
          rgba="0.792156862745098 0.819607843137255 0.933333333333333 1" />
      </material>
    </visual>
    <collision>
      <origin
        xyz="0 0 0"
        rpy="0 0 0" />
      <geometry>
        <mesh
          filename="package://hanyang_gripper_isaac_description/meshes/finger_1_2_link.STL" />
      </geometry>
    </collision>
  </link>
  <joint
    name="finger_1_2_joint"
    type="revolute">
    <origin
      xyz="-0.0073247 -0.16797 -0.032691"
      rpy="1.5708 0 3.1416" />
    <parent
      link="finger_1_1_link" />
    <child
      link="finger_1_2_link" />
    <axis
      xyz="0 -1 0" />
    <dynamics damping="10.0"/>
    <limit
      lower="-0.13963"
      upper="0.34907"
      effort="20"
      velocity="10" />
  </joint>
  <link
    name="finger_2_1_link">
    <inertial>
      <origin
        xyz="0.00349284544119963 -0.0500250494496162 -0.0210812928154636"
        rpy="0 0 0" />
      <mass
        value="0.154570338845147" />
      <inertia
        ixx="3.89039859841051E-05"
        ixy="2.89920891011328E-06"
        ixz="1.14231873888314E-06"
        iyy="4.83952164705115E-05"
        iyz="-7.44428159399651E-07"
        izz="4.54599284933065E-05" />
    </inertial>
    <visual>
      <origin
        xyz="0 0 0"
        rpy="0 0 0" />
      <geometry>
        <mesh
          filename="package://hanyang_gripper_isaac_description/meshes/finger_2_1_link.STL" />
      </geometry>
      <material
        name="">
        <color
          rgba="0.792156862745098 0.819607843137255 0.933333333333333 1" />
      </material>
    </visual>
    <collision>
      <origin
        xyz="0 0 0"
        rpy="0 0 0" />
      <geometry>
        <mesh
          filename="package://hanyang_gripper_isaac_description/meshes/finger_2_1_link.STL" />
      </geometry>
    </collision>
  </link>
  <joint
    name="finger_2_1_joint"
    type="prismatic">
    <origin
      xyz="0.0047012 -0.075026 0.22997"
      rpy="1.5708 0 -1.0472" />
    <parent
      link="eef" />
    <child
      link="finger_2_1_link" />
    <axis
      xyz="1 0 0" />
    <dynamics damping="10.0"/>
    <limit
      lower="0"
      upper="0.129"
      effort="20"
      velocity="10" />
  </joint>
  <link
    name="finger_2_2_link">
    <inertial>
      <origin
        xyz="0.0198331264051502 0.00172194131414377 -0.0278026112037169"
        rpy="0 0 0" />
      <mass
        value="0.0245510398621431" />
      <inertia
        ixx="2.82123034158343E-06"
        ixy="-4.48239267312543E-09"
        ixz="1.31636096308731E-06"
        iyy="5.58049832916389E-06"
        iyz="2.68002635228861E-08"
        izz="5.02623153873332E-06" />
    </inertial>
    <visual>
      <origin
        xyz="0 0 0"
        rpy="0 0 0" />
      <geometry>
        <mesh
          filename="package://hanyang_gripper_isaac_description/meshes/finger_2_2_link.STL" />
      </geometry>
      <material
        name="">
        <color
          rgba="0.792156862745098 0.819607843137255 0.933333333333333 1" />
      </material>
    </visual>
    <collision>
      <origin
        xyz="0 0 0"
        rpy="0 0 0" />
      <geometry>
        <mesh
          filename="package://hanyang_gripper_isaac_description/meshes/finger_2_2_link.STL" />
      </geometry>
    </collision>
  </link>
  <joint
    name="finger_2_2_joint"
    type="revolute">
    <origin
      xyz="0.023051 -0.16797 -0.032691"
      rpy="1.5708 0 -3.1416" />
    <parent
      link="finger_2_1_link" />
    <child
      link="finger_2_2_link" />
    <axis
      xyz="0 -1 0" />
    <dynamics damping="10.0"/>
    <limit
      lower="-0.13963"
      upper="0.34907"
      effort="20"
      velocity="10" />
  </joint>
</robot>