<?xml version="1.0" ?>
<!-- =================================================================================== -->
<!-- |    This document was autogenerated by xacro from pusher.xacro                   | -->
<!-- |    EDITING THIS FILE BY HAND IS NOT RECOMMENDED                                 | -->
<!-- =================================================================================== -->
<robot name="pusher">
  <link name="base_link">
    <inertial>
      <mass value="0.05"/>
      <inertia ixx="0.000016667" ixy="0" ixz="0" iyy="0.000016667" iyz="0" izz="0.000016667"/>
    </inertial>
    <visual>
      <geometry>
        <box size="0.0 0.0 0.0"/>
      </geometry>
    </visual>
  </link>
  <link name="link1">
    <inertial>
      <mass value="0.05"/>
      <inertia ixx="0.000016667" ixy="0" ixz="0" iyy="0.000016667" iyz="0" izz="0.000016667"/>
    </inertial>
    <visual>
      <geometry>
        <box size="0.0 0.0 0.0"/>
      </geometry>
    </visual>
  </link>
  <joint name="joint1" type="prismatic">
    <parent link="base_link"/>
    <child link="link1"/>
    <axis xyz="1 0 0"/>
    <dynamics damping="10.0"/>
    <limit effort="10" lower="-10" upper="10" velocity="10"/>
  </joint>
  <link name="link2">
    <inertial>
      <mass value="0.05"/>
      <inertia ixx="0.000016667" ixy="0" ixz="0" iyy="0.000016667" iyz="0" izz="0.000016667"/>
    </inertial>
    <visual>
      <geometry>
        <box size="0.0 0.0 0.0"/>
      </geometry>
    </visual>
  </link>
  <joint name="joint2" type="prismatic">
    <origin rpy="0 0 0" xyz="0 0 0"/>
    <parent link="link1"/>
    <child link="link2"/>
    <axis xyz="0 1 0"/>
    <dynamics damping="10.0"/>
    <limit effort="10" lower="-10" upper="10" velocity="10"/>
  </joint>
  <link name="eef_z">
    <inertial>
      <mass value="0.05"/>
      <inertia ixx="0.000016667" ixy="0" ixz="0" iyy="0.000016667" iyz="0" izz="0.000016667"/>
    </inertial>
    <visual>
      <geometry>
        <box size="0.015 0.015 0.015"/>
      </geometry>
      <material name="eef">
        <color rgba="1 0 1 0.1"/>
      </material>
    </visual>
  </link>
  <joint name="eef_z_joint" type="revolute">
    <safety_controller k_position="100.0" k_velocity="40.0" soft_lower_limit="-2.8973" soft_upper_limit="2.8973"/>
    <parent link="link2"/>
    <child link="eef_z"/>
    <axis xyz="0 0 1"/>
    <dynamics damping="10.0"/>
    <limit effort="10" lower="-10" upper="10" velocity="10"/>
  </joint>
  <link name="eef_y">
    <inertial>
      <mass value="0.05"/>
      <inertia ixx="0.000016667" ixy="0" ixz="0" iyy="0.000016667" iyz="0" izz="0.000016667"/>
    </inertial>
    <visual>
      <geometry>
        <box size="0 0 0"/>
      </geometry>
    </visual>
  </link>
  <joint name="eef_y_joint" type="prismatic">
    <origin rpy="0 0 0" xyz="0 0 0"/>
    <parent link="eef_z"/>
    <child link="eef_y"/>
    <axis xyz="1 0 0"/>
    <dynamics damping="10.0"/>
    <limit effort="10" lower="-0.1" upper="0.1" velocity="10"/>
  </joint>
  <link name="eef_p">
    <inertial>
      <mass value="0.05"/>
      <inertia ixx="0.000016667" ixy="0" ixz="0" iyy="0.000016667" iyz="0" izz="0.000016667"/>
    </inertial>
  </link>
  <joint name="eef_p_joint" type="revolute">
    <safety_controller k_position="100.0" k_velocity="40.0" soft_lower_limit="-1.570796" soft_upper_limit="1.570796"/>
    <parent link="eef_y"/>
    <child link="eef_p"/>
    <axis xyz="0 1 0"/>
    <dynamics damping="100.0"/>
    <limit effort="100" lower="-10" upper="10" velocity="100"/>
  </joint>
  <link name="eef">
    <visual>
      <origin rpy="0 0 0" xyz="0 0 0"/>
      <geometry>
        <box size="0.015 0.015 0.015"/>
      </geometry>
      <material name="eef">
        <color rgba="1 0 1 0.1"/>
      </material>
    </visual>
  </link>
  <link name="left_finger">
    <inertial>
      <mass value="0.05"/>
      <inertia ixx="0.000585417" ixy="0" ixz="0" iyy="0.000092417" iyz="0" izz="0.000573667"/>
    </inertial>
    <visual>
      <geometry>
        <box size="0.008 0.0022 0.2"/>
      </geometry>
    </visual>
    <collision>
      <geometry>
        <box size="0.008 0.0022 0.2"/>
      </geometry>
    </collision>
  </link>
  <link name="right_finger">
    <inertial>
      <mass value="0.05"/>
      <inertia ixx="0.000585417" ixy="0" ixz="0" iyy="0.000092417" iyz="0" izz="0.000573667"/>
    </inertial>
    <visual>
      <geometry>
        <box size="0.008 0.0022 0.2"/>
      </geometry>
    </visual>
    <collision>
      <geometry>
        <box size="0.008 0.0022 0.2"/>
      </geometry>
    </collision>
  </link>
  <joint name="joint4" type="prismatic">
    <origin rpy="0 0 0" xyz="0 0.04 0.100"/>
    <parent link="eef"/>
    <child link="left_finger"/>
    <axis xyz="0 1 0"/>
    <dynamics damping="10.0"/>
    <limit effort="20" lower="-0.04" upper="0.04" velocity="10"/>
  </joint>
  <joint name="joint5" type="prismatic">
    <origin rpy="0 0 0" xyz="0 -0.04 0.100"/>
    <parent link="eef"/>
    <child link="right_finger"/>
    <axis xyz="0 -1 0"/>
    <dynamics damping="10.0"/>
    <limit effort="20" lower="-0.04" upper="0.04" velocity="10"/>
  </joint>
  <joint name="world-env_joint" type="fixed">
    <parent link="eef_p"/>
    <child link="eef"/>
    <origin rpy="0 0 0" xyz="0 0 0"/>
  </joint>
</robot>

